<mujoco model="x1_humanoid">
  <compiler angle="radian" meshdir="./assets" autolimits="true" />

  <visual>
    <global azimuth="150" elevation="-20" />
    <headlight ambient="0.3 0.3 0.3" diffuse="0.6 0.6 0.6" specular="0 0 0" />
  </visual>

  <default>
    <default class="x1">
      <default class="visual">
        <geom group="2" type="mesh" contype="0" conaffinity="0" material="x1_silver" />
      </default>
      <default class="collision">
        <geom group="3" type="capsule" contype="1" conaffinity="1" rgba=".2 .6 .2 .3" />
        <default class="foot_capsule">
          <geom type="capsule" size="0.01" />
        </default>
      </default>
      <site group="5" rgba="1 0 0 1" />
      <joint damping="1" />
    </default>
  </default>

  <asset>
    <!-- Materials -->
    <material name="x1_silver" rgba="0.7 0.7 0.7 1" />
    <material name="x1_orange" rgba="0.8 0.4 0 1" />
    <material name="x1_red" rgba="1 0.4 0.4 1" />
    <material name="x1_yellow" rgba="1 1 0.4 1" />
    <material name="x1_green" rgba="0.4 1 0.4 1" />
    <material name="x1_blue" rgba="0 0.5 1 1" />
    <material name="x1_light_green" rgba="0.8 1.0 0.8 1" />
    <material name="x1_purple" rgba="1 0.5 1 1" />

    <!-- Meshes -->
    <mesh name="mesh_base_link_simple" file="base_link_simple.STL" />

    <mesh name="mesh_waist_yaw" file="waist_yaw.STL" />
    <mesh name="mesh_waist_roll" file="waist_roll.STL" />
    <mesh name="mesh_waist_pitch" file="waist_pitch.STL" />

    <mesh name="mesh_left_shoulder_pitch" file="left_shoulder_pitch.STL" />
    <mesh name="mesh_left_shoulder_roll" file="left_shoulder_roll.STL" />
    <mesh name="mesh_left_shoulder_yaw" file="left_shoulder_yaw.STL" />
    <mesh name="mesh_left_elbow_pitch" file="left_elbow_pitch.STL" />
    <mesh name="mesh_left_elbow_yaw" file="left_elbow_yaw.STL" />

    <mesh name="mesh_right_shoulder_pitch" file="right_shoulder_pitch.STL" />
    <mesh name="mesh_right_shoulder_roll" file="right_shoulder_roll.STL" />
    <mesh name="mesh_right_shoulder_yaw" file="right_shoulder_yaw.STL" />
    <mesh name="mesh_right_elbow_pitch" file="right_elbow_pitch.STL" />
    <mesh name="mesh_right_elbow_yaw" file="right_elbow_yaw.STL" />

    <mesh name="mesh_left_hip_pitch" file="left_hip_pitch.STL" />
    <mesh name="mesh_left_hip_roll" file="left_hip_roll.STL" />
    <mesh name="mesh_left_hip_yaw" file="left_hip_yaw.STL" />
    <mesh name="mesh_left_knee_pitch" file="left_knee_pitch.STL" />
    <mesh name="mesh_left_ankle_pitch" file="left_ankle_pitch.STL" />
    <mesh name="mesh_left_ankle_roll" file="left_ankle_roll.STL" />

    <mesh name="mesh_right_hip_pitch" file="right_hip_pitch.STL" />
    <mesh name="mesh_right_hip_roll" file="right_hip_roll.STL" />
    <mesh name="mesh_right_hip_yaw" file="right_hip_yaw.STL" />
    <mesh name="mesh_right_knee_pitch" file="right_knee_pitch.STL" />
    <mesh name="mesh_right_ankle_pitch" file="right_ankle_pitch.STL" />
    <mesh name="mesh_right_ankle_roll" file="right_ankle_roll.STL" />
  </asset>

  <worldbody>
    <body name="pelvis" pos="0 0 0.62578" childclass="x1">
      <light pos="0 0 2" mode="trackcom" />
      <camera name="track" pos="0 -3 1" quat="0.850651 0.525731 0 0" mode="track" />
      <inertial pos="0.00252285 -0.00063439 0.03023409" mass="4.3041648"
        fullinertia="0.02680559 0.01083128 0.02180955 -5.49e-06 5.389e-05  -0.00011229 " />
      <freejoint name="floating_base_joint" />
      <geom class="visual" material="x1_orange" mesh="mesh_base_link_simple" />
      <geom name="pelvis_collision" class="collision" type="sphere" size="0.08" pos="0 0 0.03" />
      <site name="imu" size="0.01" pos="0 0 0" />

      <!-- Waist Chain -->
      <body name="waist_yaw_link" pos="0.00245 0 0.115534" quat="1 0 0 -2.27456e-05">
        <inertial pos="-0.0180007 1.4e-06 0.0243298"
          quat="-7.72625e-06 0.78309 -2.54549e-05 0.621909" mass="0.362519"
          diaginertia="0.000655093 0.00045823 0.000342457" />
        <joint name="waist_yaw_joint" type="hinge" axis="0 0 1" range="-3.14 3.14" />
        <geom class="visual" material="x1_red" mesh="mesh_waist_yaw" />

        <body name="waist_roll_link" pos="0 0 0.0405" quat="0.5 0.5 -0.5 -0.5">
          <inertial pos="-0.00029919 0.0003642 -0.00019197"
            quat="0.773215 -0.138631 -0.0225684 0.618394" mass="0.0341207"
            diaginertia="5.46439e-06 4.90308e-06 4.81253e-06" />
          <joint name="waist_roll_joint" type="hinge" axis="0 0 1" range="-0.5 0.5" />
          <geom class="visual" material="x1_yellow" mesh="mesh_waist_roll" />

          <body name="torso_link" pos="0 0 0" quat="0.707107 0 0.707107 0">
            <inertial pos="-0.000617851 0.206789 -0.00114246"
              quat="0.70235 0.7111 -0.0266182 -0.0182289" mass="9.08107"
              diaginertia="0.154848 0.118223 0.0621153" />
            <joint name="waist_pitch_joint" type="hinge" axis="0 0 -1" range="-0.3 1.57" />
            <geom class="visual" material="x1_green" mesh="mesh_waist_pitch" />
            <geom name="torso_collision" class="collision" size="0.05"
              fromto="0.01 0 0.08 0.01 0.4 0.08" />
            <site name="imu_in_torso" size="0.01" pos="-0.03959 -0.00224 0.14792" />

            <!-- Left Arm Chain -->
            <body name="left_shoulder_pitch_link" pos="0 0.256 -0.1458" quat="0 0 0 -1" gravcomp="0">
              <inertial pos="-0.00251212 -0.00149141 -0.0567447"
                quat="0.995975 -0.00474479 -0.0345991 0.0825443" mass="1.00679"
                diaginertia="0.00108562 0.000958162 0.000853398" />
              <joint name="left_shoulder_pitch_joint" type="hinge" axis="0 0 -1" range="-3.14 3.14" />
              <geom class="visual" material="x1_red" mesh="mesh_left_shoulder_pitch" />

              <body name="left_shoulder_roll_link" pos="-0.0313 0 -0.0592"
                quat="0.707105 0 -0.707108 0" gravcomp="0">
                <inertial pos="0.000154 0.0778464 -0.0271134"
                  quat="0.765297 0.643563 -0.00747942 0.00959688" mass="0.691695"
                  diaginertia="0.00133677 0.00119611 0.000636982" />
                <joint name="left_shoulder_roll_joint" type="hinge" axis="0 0 -1" range="-3.14 0.0" />
                <geom class="visual" material="x1_yellow" mesh="mesh_left_shoulder_roll" />

                <body name="left_shoulder_yaw_link" pos="0 0.1252 -0.0313" quat="0.5 0.5 0.5 -0.5"
                  gravcomp="0">
                  <inertial pos="-2.68e-06 0.00182113 -0.00392718"
                    quat="0.695603 -0.0321904 0.0318975 0.716996" mass="0.725594"
                    diaginertia="0.00118335 0.00116041 0.000481204" />
                  <joint name="left_shoulder_yaw_joint" type="hinge" axis="0 0 1" range="-3.14 3.14" />
                  <geom class="visual" material="x1_green" mesh="mesh_left_shoulder_yaw" />
                  <geom name="left_shoulder_yaw_collision" class="collision" size="0.035"
                    fromto="0 0 -0.08 0 0 0.05" />

                  <body name="left_elbow_pitch_link" pos="0 -0.031 -0.0365"
                    quat="0.707107 -0.707107 0 0" gravcomp="0">
                    <inertial pos="2.604e-05 0.0752824 0.0268658"
                      quat="0.597053 0.802202 -2.17373e-05 0.000362389" mass="0.697801"
                      diaginertia="0.00116267 0.00100065 0.000614359" />
                    <joint name="left_elbow_pitch_joint" type="hinge" axis="0 0 1" range="0.0 1.7" />
                    <geom class="visual" material="x1_blue" mesh="mesh_left_elbow_pitch" />
                    <geom name="left_elbow_collision" class="collision" size="0.035"
                      fromto="-0.01 0 -0.01 0.08 0 -0.01" />

                    <body name="left_elbow_yaw_link" pos="0 0.117 0.031"
                      quat="0.499999 0.499999 -0.500001 0.500001" gravcomp="0">
                      <inertial pos="-0.00441829 -0.0011133 -0.0671345"
                        quat="0.990089 0.12403 0.00491944 -0.065691" mass="0.803869"
                        diaginertia="0.00198622 0.00186177 0.000729748" />
                      <joint name="left_elbow_yaw_joint" type="hinge" axis="0 0 1"
                        range="-3.14 3.14" />
                      <geom class="visual" material="x1_light_green" mesh="mesh_left_elbow_yaw" />
                      <geom name="left_hand_collision" class="collision" size="0.035"
                        fromto="0 0 -0.05 0 0 -0.12" />
                      <site name="left_palm" pos="0 0 -0.1" size="0.01" />
                    </body>
                  </body>
                </body>
              </body>
            </body>

            <!-- Right Arm Chain -->
            <body name="right_shoulder_pitch_link" pos="0 0.256 0.1458" quat="-3.67321e-06 1 0 0"
              gravcomp="0">
              <inertial pos="0.00250704 -0.00149173 -0.0567433"
                quat="0.995977 -0.00568417 0.0346063 -0.0824611" mass="1.00679"
                diaginertia="0.00108562 0.000958168 0.000853396" />
              <joint name="right_shoulder_pitch_joint" type="hinge" axis="0 0 1" range="-3.14 3.14" />
              <geom class="visual" material="x1_red" mesh="mesh_right_shoulder_pitch" />

              <body name="right_shoulder_roll_link" pos="0.0313 0 -0.0592"
                quat="-2.59734e-06 0.707105 2.59735e-06 0.707108" gravcomp="0">
                <inertial pos="9.998e-05 -0.0778724 -0.0270563"
                  quat="0.64355 0.765355 0.0062383 -0.00599871" mass="0.691426"
                  diaginertia="0.00133761 0.00119704 0.000636294" />
                <joint name="right_shoulder_roll_joint" type="hinge" axis="0 0 1" range="-3.14 0.0" />
                <geom class="visual" material="x1_yellow" mesh="mesh_right_shoulder_roll" />

                <body name="right_shoulder_yaw_link" pos="0 -0.1252 -0.0313"
                  quat="0.707105 0.707108 0 0" gravcomp="0">
                  <inertial pos="-0.00189082 -0.00017102 0.0317511"
                    quat="0.694675 -0.204745 -0.19648 0.660985" mass="0.604503"
                    diaginertia="0.000550567 0.000505158 0.000491905" />
                  <joint name="right_shoulder_yaw_joint" type="hinge" axis="0 0 1"
                    range="-3.14 3.14" />
                  <geom class="visual" material="x1_green" mesh="mesh_right_shoulder_yaw" />
                  <geom name="right_shoulder_yaw_collision" class="collision" size="0.035"
                    fromto="0 0 -0.08 0 0 0.05" />

                  <body name="right_elbow_pitch_link" pos="-0.031 0 0.0365" quat="0.5 -0.5 0.5 -0.5"
                    gravcomp="0">
                    <inertial pos="-2.604e-05 -0.0752983 0.0268563"
                      quat="0.802034 0.597278 0.000362597 -2.24278e-05" mass="0.697801"
                      diaginertia="0.00116302 0.00100116 0.000614171" />
                    <joint name="right_elbow_pitch_joint" type="hinge" axis="0 0 -1" range="0.0 1.7" />
                    <geom class="visual" material="x1_blue" mesh="mesh_right_elbow_pitch" />
                    <geom name="right_elbow_collision" class="collision" size="0.035"
                      fromto="-0.01 0 -0.01 0.08 0 -0.01" />

                    <body name="right_elbow_yaw_link" pos="0 -0.117 0.031"
                      quat="0.499999 -0.499999 -0.500001 -0.500001" gravcomp="0">
                      <inertial pos="-0.00403154 -0.00910945 -0.047197"
                        quat="0.994559 0.0793425 -0.0232128 -0.0633939" mass="0.573838"
                        diaginertia="0.00105729 0.000985489 0.000647245" />
                      <joint name="right_elbow_yaw_joint" type="hinge" axis="0 0 -1"
                        range="-3.14 3.14" />
                      <geom class="visual" material="x1_light_green" mesh="mesh_right_elbow_yaw" />
                      <geom name="right_hand_collision" class="collision" size="0.035"
                        fromto="0 0 -0.05 0 0 -0.12" />
                      <site name="right_palm" pos="0 0 -0.1" size="0.01" />
                    </body>
                  </body>
                </body>
              </body>
            </body>
          </body>
        </body>
      </body>

      <!-- Left Leg Chain -->
      <body name="left_hip_pitch_link" pos="0.00245 0.092277 -0.012143"
        quat="0.65328 0.270599 -0.270598 0.653282" gravcomp="0">
        <inertial pos="-4.816e-05 -0.0107584 -0.0540778"
          quat="0.701067 -0.0888726 0.120485 0.697202" mass="1.67336"
          diaginertia="0.00256418 0.00234466 0.00215142" />
        <joint name="left_hip_pitch_joint" type="hinge" axis="0 0 1" range="-3.14 6.28" />
        <geom class="visual" material="x1_red" mesh="mesh_left_hip_pitch" />

        <body name="left_hip_roll_link" pos="0 -0.0405 -0.0589"
          quat="0.653281 0.653281 0.270598 -0.270598" gravcomp="0">
          <inertial pos="0.00014604 -0.0412348 -0.0101534"
            quat="0.30122 0.638429 -0.639374 0.304757" mass="0.285622"
            diaginertia="0.000612958 0.000557294 0.000275288" />
          <joint name="left_hip_roll_joint" type="hinge" axis="0 0 -1" range="-2.3 0.8" />
          <geom class="visual" material="x1_yellow" mesh="mesh_left_hip_roll" />
          <geom name="left_hip_collision" class="collision" size="0.06"
            fromto="0 -0.02 0 0 -0.08 -0.04" />

          <body name="left_hip_yaw_link" pos="0 -0.0838049 -0.0406" quat="0.707107 0.707107 0 0"
            gravcomp="0">
            <inertial pos="-0.00212295 -3.062e-05 0.0916484"
              quat="0.999467 0.000387515 -0.0324521 -0.0035558" mass="2.73696"
              diaginertia="0.0127474 0.0124495 0.00338744" />
            <joint name="left_hip_yaw_joint" type="hinge" axis="0 0 -1" range="-3.14 3.14" />
            <geom class="visual" material="x1_green" mesh="mesh_left_hip_yaw" />
            <geom name="left_thigh_collision" class="collision" size="0.055"
              fromto="-0.0 0 -0.03 -0.06 0 0.14" />

            <body name="left_knee_link" pos="-0.0337 0 0.1422" quat="0.5 -0.5 0.5 -0.5" gravcomp="0">
              <inertial pos="-0.000466573 -0.136803 0.0283565"
                quat="0.549096 0.504801 -0.427727 0.510606" mass="1.68649"
                diaginertia="0.00989796 0.00939201 0.00196477" />
              <joint name="left_knee_pitch_joint" type="hinge" axis="0 0 1" range="0.0 1.8" />
              <geom class="visual" material="x1_blue" mesh="mesh_left_knee_pitch" />
              <geom name="left_shin_collision" class="collision" size="0.045"
                fromto="0.01 0 0 0.01 -0.15 0" />
              <geom name="left_linkage_brace_collision" class="collision" size="0.03"
                fromto="0.01 -0.2 0 0.01 -0.28 0" />

              <body name="left_ankle_pitch_link" pos="0 -0.30494 0.0336" quat="0 0 -1 0"
                gravcomp="0">
                <inertial pos="-2.32e-06 7.077e-05 -2.048e-05" quat="0.707107 0 0 0.707107"
                  mass="0.0621721" diaginertia="2.373e-05 2.273e-05 6.68e-06" />
                <joint name="left_ankle_pitch_joint" type="hinge" axis="0 0 -1" range="-1.0 1.0" />
                <geom class="visual" material="x1_light_green" mesh="mesh_left_ankle_pitch" />

                <body name="left_ankle_roll_link" pos="0 0 0" quat="0.707107 0 0.707107 0"
                  gravcomp="0">
                  <inertial pos="0.00017156 -0.025247 -0.00019936"
                    quat="0.707585 0.0111979 -0.0139853 0.706401" mass="0.589712"
                    diaginertia="0.00190069 0.00152114 0.000541391" />
                  <joint name="left_ankle_roll_joint" type="hinge" axis="0 0 1" range="-1.0 1.0" />
                  <geom class="visual" material="x1_purple" mesh="mesh_left_ankle_roll" />

                  <!-- Left Foot Collision - Optimized with capsules -->
                  <site name="left_foot" pos="0.04 -0.0408 0" size="0.01" />
                  <!-- 7 个横向 capsule，椭圆形（顺时针旋转 90°） -->
                  <geom name="left_foot1_collision" class="foot_capsule"
                    fromto="-0.045 -0.0408  0.06  -0.045 -0.0408 -0.05" />
                  <geom name="left_foot2_collision" class="foot_capsule"
                    fromto="-0.037 -0.0408  0.086  -0.037 -0.0408 -0.076" />
                  <geom name="left_foot3_collision" class="foot_capsule"
                    fromto="-0.018 -0.0408  0.095  -0.018 -0.0408 -0.085" />
                  <geom name="left_foot4_collision" class="foot_capsule"
                    fromto="0.000 -0.0408  0.098   0.000 -0.0408 -0.088" />
                  <geom name="left_foot5_collision" class="foot_capsule"
                    fromto="0.018 -0.0408  0.095   0.018 -0.0408 -0.085" />
                  <geom name="left_foot6_collision" class="foot_capsule"
                    fromto="0.037 -0.0408  0.086   0.037 -0.0408 -0.076" />
                  <geom name="left_foot7_collision" class="foot_capsule"
                    fromto="0.045 -0.0408  0.06   0.045 -0.0408 -0.05" />
                </body>
              </body>
            </body>
          </body>
        </body>
      </body>

      <!-- Right Leg Chain -->
      <body name="right_hip_pitch_link" pos="0.00245 -0.092277 -0.012143"
        quat="0.65328 -0.270599 -0.270598 -0.653282" gravcomp="0">
        <inertial pos="-0.00011915 0.0106148 -0.0540773"
          quat="0.704635 0.117558 -0.0919818 0.693692" mass="1.66657"
          diaginertia="0.00254519 0.00232121 0.00213313" />
        <joint name="right_hip_pitch_joint" type="hinge" axis="0 0 1" range="-6.28 3.14" />
        <geom class="visual" material="x1_red" mesh="mesh_right_hip_pitch" />

        <body name="right_hip_roll_link" pos="0 0.0405 -0.0589"
          quat="0.653281 0.653281 0.270598 -0.270598" gravcomp="0">
          <inertial pos="-0.00027058 -0.0416462 0.0103426"
            quat="0.633195 0.29395 -0.315414 0.642785" mass="0.287688"
            diaginertia="0.000626566 0.000566795 0.000280389" />
          <joint name="right_hip_roll_joint" type="hinge" axis="0 0 1" range="-0.8 2.3" />
          <geom class="visual" material="x1_yellow" mesh="mesh_right_hip_roll" />
          <geom name="right_hip_collision" class="collision" size="0.06"
            fromto="0 0.02 0 0 0.08 -0.04" />

          <body name="right_hip_yaw_link" pos="0 -0.0777549 0.0406"
            quat="0.7071 -0.7071 -0.00304418 0.00304418" gravcomp="0">
            <inertial pos="-0.00241642 1.672e-05 -0.097047"
              quat="0.999478 -0.000259753 0.0322929 -0.00102692" mass="2.69635"
              diaginertia="0.0125794 0.0122506 0.00332533" />
            <joint name="right_hip_yaw_joint" type="hinge" axis="0 0 1" range="-3.14 3.14" />
            <geom class="visual" material="x1_green" mesh="mesh_right_hip_yaw" />
            <geom name="right_thigh_collision" class="collision" size="0.055"
              fromto="-0.0 0 -0.03 -0.06 0 -0.17" />

            <body name="right_knee_link" pos="-0.0347752 0 -0.147956"
              quat="0.497843 0.502148 0.502148 0.497843" gravcomp="0">
              <inertial pos="0.000491832 -0.13745 0.0283321"
                quat="0.511647 0.42723 -0.504967 0.548361" mass="1.68377"
                diaginertia="0.00984174 0.00933685 0.00195957" />
              <joint name="right_knee_pitch_joint" type="hinge" axis="0 0 -1" range="0.0 1.8" />
              <geom class="visual" material="x1_blue" mesh="mesh_right_knee_pitch" />
              <geom name="right_shin_collision" class="collision" size="0.045"
                fromto="0.01 0 0 0.01 -0.15 0" />
              <geom name="right_linkage_brace_collision" class="collision" size="0.03"
                fromto="0.01 -0.2 0 0.01 -0.28 0" />

              <body name="right_ankle_pitch_link" pos="0 -0.30494 0.0336" quat="0 1 0 0"
                gravcomp="0">
                <inertial pos="2.47e-06 -7.076e-05 -1.763e-05"
                  quat="0.707107 -0.000207363 0.000207363 0.707107" mass="0.0621721"
                  diaginertia="2.373e-05 2.273e-05 6.67999e-06" />
                <joint name="right_ankle_pitch_joint" type="hinge" axis="0 0 1" range="-1.0 1.0" />
                <geom class="visual" material="x1_light_green" mesh="mesh_right_ankle_pitch" />

                <body name="right_ankle_roll_link" pos="0 0 0" quat="0.707107 0 0.707107 0"
                  gravcomp="0">
                  <inertial pos="-2.32e-06 0.0250789 0.00010556"
                    quat="0.707007 -0.0123369 0.0123002 0.706992" mass="0.591828"
                    diaginertia="0.00189406 0.00151845 0.00054237" />
                  <joint name="right_ankle_roll_joint" type="hinge" axis="0 0 1" range="-1.0 1.0" />
                  <geom class="visual" material="x1_purple" mesh="mesh_right_ankle_roll" />

                  <!-- Right Foot Collision - Optimized with capsules -->
                  <site name="right_foot" pos="0.04 0.0408 0" size="0.01" />
                  <!-- 7 个横向 capsule，椭圆形（中间长，两边短） -->
                  <geom name="right_foot1_collision" class="foot_capsule"
                    fromto="-0.045 0.0408  0.06  -0.045 0.0408 -0.05" />
                  <geom name="right_foot2_collision" class="foot_capsule"
                    fromto="-0.037 0.0408  0.086  -0.037 0.0408 -0.076" />
                  <geom name="right_foot3_collision" class="foot_capsule"
                    fromto="-0.018 0.0408  0.095  -0.018 0.0408 -0.085" />
                  <geom name="right_foot4_collision" class="foot_capsule"
                    fromto="0.000 0.0408  0.098   0.000 0.0408 -0.088" />
                  <geom name="right_foot5_collision" class="foot_capsule"
                    fromto="0.018 0.0408  0.095   0.018 0.0408 -0.085" />
                  <geom name="right_foot6_collision" class="foot_capsule"
                    fromto="0.037 0.0408  0.086   0.037 0.0408 -0.076" />
                  <geom name="right_foot7_collision" class="foot_capsule"
                    fromto="0.045 0.0408  0.06   0.045 0.0408 -0.05" />
                </body>
              </body>
            </body>
          </body>
        </body>
      </body>
    </body>
  </worldbody>

  <contact>
    <!-- Exclude inappropriate collisions -->
    <exclude body1="pelvis" body2="left_hip_roll_link" />
    <exclude body1="pelvis" body2="right_hip_roll_link" />
    <exclude body1="left_elbow_pitch_link" body2="left_shoulder_yaw_link" />
    <exclude body1="right_elbow_pitch_link" body2="right_shoulder_yaw_link" />
    <exclude body1="torso_link" body2="left_shoulder_pitch_link" />
    <exclude body1="torso_link" body2="right_shoulder_pitch_link" />
  </contact>

</mujoco>